Workbook

Sheet ReadMe
A1: YOUR TRAINING & NUTRITION SYSTEM — built 27 Aug 2026
A3: HOW THIS WORKBOOK FITS TOGETHER
B5: Split | C5: The weekly schedule. Which day you train what, how the flexible Friday works, and why this split beats the one you were running.
B6: Workouts | C6: The actual sessions. Column B is the exercise you do first choice. Column C (green) and Column D (cream) are your substitutes if the machine is taken or your gym doesn't have it — same convention as your old sheet.
B7: WeightRamp | C7: Exactly what to load on the bar in each of the next 12 weeks, worked back from the numbers in the sheet you sent me. This is the sheet that answers 'when can I lift my old weights again'.
B8: Nutrition | C8: Calories, protein, carbs, fat, fibre and water. Every number is a formula off your bodyweight — change the weight in B5 and the whole sheet updates. Includes the weekend junk-food budget.
B9: Nutrients | C9: Omega-3, vitamin D, magnesium, zinc and the rest, with the specific foods that get you there. Shrimp, chia, the lot.
B10: Tracker | C10: Log 8 numbers once a week. The last two columns tell you if you're on pace and what specifically to fix.
B11: Milestones | C11: The staged goals between now and month 6, and a blunt list of what fails if you skip each input.
A13: COLOUR LEGEND (matches your original sheet)
B15: White cell | C15: First-choice exercise. Do this one if the equipment is free.
B16: Green cell | C16: Alternative 1 — machine or cable version. Same muscle, same job.
B17: Cream cell | C17: Alternative 2 — dumbbell or bodyweight version. Works in any gym, however basic.
B18: Yellow cell | C18: An input. You type here. Everything else calculates itself — don't overwrite formulas.
A20: FOUR THINGS TO READ BEFORE YOU START
B22: • | C22: Your old split was fine. Your old volume was the problem.
C23: Back+tricep / chest+bicep / shoulder+crunches hits each muscle roughly once a week. A 2016 Schoenfeld meta-analysis and everything since points the same way: at matched volume, twice-weekly beats once-weekly for both size and strength. The plan here hits everything 2x/week in four sessions. Nothing exotic — just better spacing.
B25: • | C25: You cannot choose where fat comes off.
C26: Spot reduction isn't a thing. Crunches build the muscle underneath; they do not thin the layer on top. Belly fat goes when total body fat goes, and the order it leaves in is genetic. The abs you want are made almost entirely in the Nutrition sheet. Training just makes sure there's something to see when the fat clears.
B28: • | C28: Your old weights are a week 7-9 target, not a week 3 target.
C29: Three weeks off costs a trained lifter very little — the research on short layoffs shows trivial strength loss at three weeks. But you weren't running that college program up until three weeks ago; you were running a lighter one for a long stretch before that. So the gap isn't three weeks wide. Expect to be back at your old bench and squat around week 7-9, and you'll get there faster than a beginner would because myonuclei from that earlier training stay put. The WeightRamp sheet paces it.
B31: • | C31: You are not going to get bulky. That is not the risk here.
C32: You're eating in a deficit at 79kg heading to 76kg. Building noticeable size in a deficit at your training age essentially doesn't happen. Lifting heavy while cutting is what stops you losing muscle — without it, 25-40% of what you lose comes off as lean mass. The heavy work protects the physique you're after.
A34: ON THE STRESS EATING
C36: You said you'd rather not cut sweets and junk entirely, and that you eat them at the weekend. This plan is built around that rather than against it. The Nutrition sheet runs a weekly calorie budget instead of a daily one: you eat slightly under target Monday to Friday, which banks roughly 400-600 spare calories for each weekend day. That is a real dessert or a real takeaway, planned in, not a failure. Diets that ban the thing you reliably eat anyway are the ones that end in week three. Worth naming the other half of it though: you described the eating as stress-driven and tied to overthinking. Protein and a gym routine genuinely help — high-protein meals blunt appetite, and training is one of the better stress regulators going. But they treat the symptom. If the overthinking is heavy enough that it's running your eating, that part is worth its own attention, separate from anything in this workbook.

Sheet Split
A1: THE SPLIT — Upper / Lower, four sessions minimum, five when Friday allows
A3: WHY THIS ONE
A5: You asked whether Push/Pull/Legs is ideal. For your schedule, no — and the reason is arithmetic rather than anything about the exercises. PPL divides into three. Your week divides into four or five. Run PPL across four days and the rotation drifts: some weeks a muscle gets trained twice, some weeks once, and you can never quite plan Friday. Upper/Lower divides into four cleanly, so every muscle is trained exactly twice every week, every week, and the fifth day becomes a genuine bonus rather than a thing the program depends on. The current evidence is fairly settled that split structure itself matters less than weekly volume and frequency: a 2024 meta-analysis of 14 studies found no hypertrophy difference between split types once volume was equalised. So the deciding factor is which structure you'll actually complete — and on that, one 12-month dataset comparing matched lifters found a 3-4% strength difference between PPL and Upper/Lower but a 31% difference in adherence. Pick the one that survives contact with a 9-to-5 and a Friday football game.
A7: THE WEEK
A8: Day | B8: Session | C8: Focus | D8: Time | E8: Priority | F8: Notes
A9: Monday | B9: Day A | C9: Upper — push emphasis | D9: 80-85 min | E9: Non-negotiable | F9: Chest, shoulders, triceps lead. Back and biceps get a small share. Hardest pressing of the week — do it when you're freshest.
A10: Tuesday | B10: Day B | C10: Lower — quad emphasis | D10: 80-85 min | E10: Non-negotiable | F10: Squat-led. Finish with 12 min of intervals — legs are already warm and you're not lifting tomorrow.
A11: Wednesday | B11: Rest | C11: Walk / mobility | D11: 20-30 min | E11: Easy | F11: Not a gym day. Walk 8,000+ steps, ten minutes of hips and thoracic spine. Sitting at a desk five days a week is the thing this is countering.
A12: Thursday | B12: Day C | C12: Upper — pull emphasis | D12: 80-85 min | E12: Non-negotiable | F12: Back and biceps lead. This is the day that fixes desk posture, so don't be the person who skips it for another chest day.
A13: Friday | B13: Day D OR Sport | C13: Lower — posterior chain | D13: 80-85 min | E13: Flexible | F13: If you're playing pickleball or football, play. The sport covers your conditioning for the day and Day D moves to Saturday. If you're not playing, lift.
A14: Saturday | B14: Day D or Day E | C14: Whatever Friday didn't cover | D14: 60-85 min | E14: Flexible | F14: Friday lifted → do Day E here (the optional fifth). Friday played sport → do Day D here. Friday did nothing → do Day D here and Day E becomes optional.
A15: Sunday | B15: Rest | C15: Full rest | D15: — | E15: Protected | F15: Meal prep, weigh in, fill the Tracker. Genuinely rest — recovery is when the adaptation happens, not the training.
A17: THE THREE SCENARIOS, SPELLED OUT
A18: Scenario | B18: Mon | C18: Tue | D18: Thu | E18: Fri | F18: Sat
A19: 4 days — sport on Friday | B19: A | C19: B | D19: C | E19: Pickleball / football | F19: D
A20: 5 days — no sport | B20: A | C20: B | D20: C | E20: D | F20: E (optional)
A21: 4 days — no sport, want the weekend free | B21: A | C21: B | D21: C | E21: D | F21: Rest
A23: Days A-D are the program. Day E is a bonus that mops up side delts, arms and core — skip it in a busy week and you lose nothing structural. Never skip two of A-D in the same week: that's the point where a muscle drops to once-weekly frequency and the whole rationale for the split evaporates.
A26: WEEKLY VOLUME CHECK — hard sets per muscle, 4-day version
A27: Muscle | B27: Sets/wk | C27: Research range | D27: Verdict
A28: Chest | B28: 11 | C28: 10-20 | D28: In range
A29: Back / lats | B29: 13 | C29: 10-20 | D29: In range
A30: Side delts | B30: 9 | C30: 8-16 | D30: In range — Day E adds 3 more
A31: Rear delts | B31: 6 | C31: 6-12 | D31: Adequate, posture-driven
A32: Biceps | B32: 8 | C32: 6-14 | D32: In range
A33: Triceps | B33: 9 | C33: 6-14 | D33: In range
A34: Quads | B34: 12 | C34: 10-20 | D34: In range
A35: Hamstrings / glutes | B35: 11 | C35: 10-20 | D35: In range
A36: Calves | B36: 8 | C36: 6-16 | D36: In range
A37: Core / abs | B37: 11 | C37: 8-16 | D37: Trained 4x/wk, direct and heavy
A39: Source for the 10-20 range: Schoenfeld et al. 2017 dose-response work and the Pelland et al. 2025 volume meta-analysis. Everything above sits inside it deliberately — in a calorie deficit, recovery is the constraint, and piling on sets you can't recover from costs you rather than buys you anything.

Sheet Workouts
A1: THE SESSIONS — first choice, then two substitutes
A3: Column B is what you do if the equipment is free. Column C (green) swaps to a machine or cable. Column D (cream) is the dumbbell or bodyweight version that works in any gym, however minimal the kit. All three train the same thing — there is no penalty for using column D every session. 'Wk1 kg' pulls from the WeightRamp sheet; where it says 'RPE', pick a weight where the last rep is genuinely hard but you'd have 2 clean reps left.
A5: DAY A — UPPER, PUSH EMPHASIS ~80 min Chest · Shoulders · Triceps · Core
A6: # | B6: Exercise (first choice) | C6: Alternative 1 — machine / cable | D6: Alternative 2 — dumbbell / bodyweight | E6: Sets x Reps | F6: Intensity | G6: Rest | H6: Target | I6: Wk1 kg | J6: Coaching note
A7: 1 | B7: Barbell Bench Press | C7: Machine Chest Press | D7: Flat Dumbbell Press | E7: 4 x 5-7 | F7: RPE 8 | G7: 2-3 min | H7: Chest, triceps | I7: =IFERROR(INDEX(WeightRamp!$C$7:$C$30,MATCH($B7,WeightRamp!$A$7:$A$30,0)),"RPE") -> 40 | J7: Your main pressing lift. Bar to mid-chest, elbows ~45 degrees, feet planted. Add weight only when all 4 sets hit the top of the range.
A8: 2 | B8: Standing Overhead Press | C8: Machine Shoulder Press | D8: Seated Dumbbell Press | E8: 3 x 6-8 | F8: RPE 8 | G8: 2-3 min | H8: Front delts, triceps | I8: =IFERROR(INDEX(WeightRamp!$C$7:$C$30,MATCH($B8,WeightRamp!$A$7:$A$30,0)),"RPE") -> 27.5 | J8: Squeeze glutes and brace so it doesn't turn into a standing incline press. Bar path just past the nose.
A9: 3 | B9: Incline Dumbbell Press | C9: Incline Machine Press | D9: Deficit Push-up (hands on books) | E9: 3 x 8-10 | F9: RPE 9 | G9: 90 sec | H9: Upper chest | I9: =IFERROR(INDEX(WeightRamp!$C$7:$C$30,MATCH($B9,WeightRamp!$A$7:$A$30,0)),"RPE") -> 12.5 | J9: 30-45 degree bench. This is the angle that fills out the top of the chest — the bit that reads as 'in shape' in a t-shirt.
A10: 4 | B10: Dumbbell Lateral Raise | C10: Cable Lateral Raise | D10: Egyptian Lateral Raise | E10: 3 x 12-15 | F10: RPE 9-10 | G10: 60 sec | H10: Side delts | I10: =IFERROR(INDEX(WeightRamp!$C$7:$C$30,MATCH($B10,WeightRamp!$A$7:$A$30,0)),"RPE") -> 7.5 | J10: You already know this one. Light, slow, no swinging. Last set: myo-reps — go to failure, rest 15 sec, 3-4 more reps, repeat twice. Side delts are the single best return on effort for looking leaner than you are.
A11: 5 | B11: Overhead Cable Tricep Ext. | C11: EZ-Bar Skull Crusher | D11: Overhead Dumbbell Extension | E11: 3 x 10-12 | F11: RPE 9 | G11: 75 sec | H11: Triceps (long head) | I11: =IFERROR(INDEX(WeightRamp!$C$7:$C$30,MATCH($B11,WeightRamp!$A$7:$A$30,0)),"RPE") -> 20 | J11: Overhead beats pushdowns for the long head — that's the mass of the arm. Keep elbows in and still.
A12: 6 | B12: Dips | C12: Assisted Dip Machine | D12: Bench Dips | E12: 2 x AMRAP | F12: RPE 9 | G12: 90 sec | H12: Chest, triceps | I12: =IFERROR(INDEX(WeightRamp!$C$7:$C$30,MATCH($B12,WeightRamp!$A$7:$A$30,0)),"RPE") -> RPE | J12: Stop 1-2 reps short of total failure. Slight forward lean for chest, upright for triceps.
A13: 7 | B13: Hanging Leg Raise | C13: Captain's Chair Knee Raise | D13: Lying Leg Raise | E13: 3 x 10-15 | F13: RPE 9 | G13: 60 sec | H13: Lower abs, hip flexors | I13: =IFERROR(INDEX(WeightRamp!$C$7:$C$30,MATCH($B13,WeightRamp!$A$7:$A$30,0)),"RPE") -> RPE | J13: Curl the pelvis up at the top rather than just swinging the legs — that's the difference between hip flexor work and abs.
A14: F | B14: 10 min Zone 2 — bike, incline walk or rower | C14: Brisk outdoor walk | D14: 10 min easy skipping | E14: 10 min | F14: Conversational | G14: — | H14: Aerobic base | I14: — | J14: Easy enough that you could hold a conversation. This is recovery work, not a second workout.
A16: DAY B — LOWER, QUAD EMPHASIS ~80 min Quads · Hamstrings · Calves · Conditioning
A17: # | B17: Exercise (first choice) | C17: Alternative 1 — machine / cable | D17: Alternative 2 — dumbbell / bodyweight | E17: Sets x Reps | F17: Intensity | G17: Rest | H17: Target | I17: Wk1 kg | J17: Coaching note
A18: 1 | B18: Back Squat | C18: Hack Squat | D18: Goblet Squat | E18: 4 x 5-7 | F18: RPE 8 | G18: 3 min | H18: Quads, glutes | I18: =IFERROR(INDEX(WeightRamp!$C$7:$C$30,MATCH($B18,WeightRamp!$A$7:$A$30,0)),"RPE") -> 30 | J18: Rebuild the pattern before you rebuild the load. Depth first, weight second — the WeightRamp column starts you deliberately light for this reason.
A19: 2 | B19: Romanian Deadlift | C19: 45-degree Back Extension | D19: Dumbbell RDL | E19: 3 x 8-10 | F19: RPE 8 | G19: 2 min | H19: Hamstrings, glutes | I19: =IFERROR(INDEX(WeightRamp!$C$7:$C$30,MATCH($B19,WeightRamp!$A$7:$A$30,0)),"RPE") -> 42.5 | J19: Hinge, don't squat. Bar stays against the legs, chest proud, stretch felt in the hamstring not the lower back.
A20: 3 | B20: Bulgarian Split Squat | C20: Smith Machine Split Squat | D20: Walking Lunge | E20: 3 x 8-10 each | F20: RPE 8-9 | G20: 90 sec | H20: Quads, glutes, balance | I20: =IFERROR(INDEX(WeightRamp!$C$7:$C$30,MATCH($B20,WeightRamp!$A$7:$A$30,0)),"RPE") -> RPE | J20: In your old sheet as the supported version. Brutal, and the best single fix for the hip stiffness a desk job builds.
A21: 4 | B21: Leg Extension | C21: Sissy Squat | D21: Reverse Nordic | E21: 3 x 12-15 | F21: RPE 9-10 | G21: 60 sec | H21: Quads (rectus femoris) | I21: =IFERROR(INDEX(WeightRamp!$C$7:$C$30,MATCH($B21,WeightRamp!$A$7:$A$30,0)),"RPE") -> 27.5 | J21: Pause a beat at the top. Only quad exercise that loads the rectus femoris in a lengthened-but-shortened position.
A22: 5 | B22: Seated Leg Curl | C22: Lying Leg Curl | D22: Nordic Ham Curl | E22: 3 x 10-12 | F22: RPE 9 | G22: 75 sec | H22: Hamstrings | I22: =IFERROR(INDEX(WeightRamp!$C$7:$C$30,MATCH($B22,WeightRamp!$A$7:$A$30,0)),"RPE") -> 27.5 | J22: Seated beats lying here — hamstrings grow better trained at longer muscle lengths.
A23: 6 | B23: Standing Calf Raise | C23: Leg Press Calf Raise | D23: Single-Leg Calf Raise | E23: 4 x 10-15 | F23: RPE 9-10 | G23: 60 sec | H23: Calves | I23: =IFERROR(INDEX(WeightRamp!$C$7:$C$30,MATCH($B23,WeightRamp!$A$7:$A$30,0)),"RPE") -> 30 | J23: Full stretch at the bottom, two-second pause. Calves need the stretch far more than they need the weight.
A24: 7 | B24: Long-Lever Plank | C24: Ab Wheel Rollout | D24: Standard Plank | E24: 3 x 30-45 sec | F24: RPE 9 | G24: 45 sec | H24: Deep core, anti-extension | I24: =IFERROR(INDEX(WeightRamp!$C$7:$C$30,MATCH($B24,WeightRamp!$A$7:$A$30,0)),"RPE") -> RPE | J24: Your old sheet had this. Arms further forward than a normal plank. Brace like you're about to take a punch.
A25: F | B25: Intervals: 6 x (30 sec hard / 90 sec easy) | C25: Rower or assault bike | D25: Hill sprints outdoors | E25: 12 min | F25: Hard / easy | G25: — | H25: VO2 max, stamina | I25: — | J25: This is your stamina lever. Two sessions a week of 4x4-style intervals reliably moves VO2max in recreational trainees — extra frequency adds little. Legs are already cooked, so this costs you nothing on the lifting.
A27: DAY C — UPPER, PULL EMPHASIS ~80 min Back · Rear delts · Biceps · Core
A28: # | B28: Exercise (first choice) | C28: Alternative 1 — machine / cable | D28: Alternative 2 — dumbbell / bodyweight | E28: Sets x Reps | F28: Intensity | G28: Rest | H28: Target | I28: Wk1 kg | J28: Coaching note
A29: 1 | B29: Pull-Up (weighted when easy) | C29: Lat Pulldown | D29: Assisted / Band Pull-Up | E29: 4 x 5-8 | F29: RPE 8 | G29: 2-3 min | H29: Lats, biceps | I29: =IFERROR(INDEX(WeightRamp!$C$7:$C$30,MATCH($B29,WeightRamp!$A$7:$A$30,0)),"RPE") -> BW | J29: Your old sheet had weighted pull-ups. Get back to bodyweight sets of 8 clean first, then start adding a belt.
A30: 2 | B30: Barbell Row | C30: Chest-Supported Row | D30: Single-Arm Dumbbell Row | E30: 3 x 8-10 | F30: RPE 8 | G30: 2 min | H30: Mid-back, lats | I30: =IFERROR(INDEX(WeightRamp!$C$7:$C$30,MATCH($B30,WeightRamp!$A$7:$A$30,0)),"RPE") -> 30 | J30: If your lower back is the limiting factor, take the chest-supported version — no shame, and it isolates the target better anyway.
A31: 3 | B31: Seated Cable Row | C31: Machine Row | D31: Inverted Row (bar or rings) | E31: 3 x 10-12 | F31: RPE 9 | G31: 90 sec | H31: Mid-back, rhomboids | I31: =IFERROR(INDEX(WeightRamp!$C$7:$C$30,MATCH($B31,WeightRamp!$A$7:$A$30,0)),"RPE") -> 27.5 | J31: Pull to the navel, elbows tight. Squeeze for a full second. This is the anti-desk-posture exercise.
A32: 4 | B32: Rope Face Pull | C32: Reverse Pec Deck | D32: Band Pull-Apart | E32: 3 x 15-20 | F32: RPE 8 | G32: 60 sec | H32: Rear delts, rotator cuff | I32: =IFERROR(INDEX(WeightRamp!$C$7:$C$30,MATCH($B32,WeightRamp!$A$7:$A$30,0)),"RPE") -> 30 | J32: Do these religiously. They're the reason your shoulders keep working while you press twice a week, and they undo eight hours of hunching.
A33: 5 | B33: Incline Dumbbell Curl | C33: Cable Curl | D33: Standing Dumbbell Curl | E33: 3 x 10-12 | F33: RPE 9 | G33: 75 sec | H33: Biceps (long head) | I33: =IFERROR(INDEX(WeightRamp!$C$7:$C$30,MATCH($B33,WeightRamp!$A$7:$A$30,0)),"RPE") -> 7.5 | J33: From your old sheet. Incline puts the long head on stretch, which is where most of the growth stimulus lives.
A34: 6 | B34: Hammer Curl | C34: Rope Hammer Curl | D34: Reverse Curl | E34: 2 x 12-15 | F34: RPE 9-10 | G34: 60 sec | H34: Brachialis, forearm | I34: =IFERROR(INDEX(WeightRamp!$C$7:$C$30,MATCH($B34,WeightRamp!$A$7:$A$30,0)),"RPE") -> 10 | J34: Brachialis sits under the bicep and pushes it up. This is what makes an arm look thick from the side.
A35: 7 | B35: Cable Crunch | C35: Decline Crunch | D35: Weighted Crunch | E35: 3 x 12-15 | F35: RPE 9 | G35: 60 sec | H35: Upper abs | I35: =IFERROR(INDEX(WeightRamp!$C$7:$C$30,MATCH($B35,WeightRamp!$A$7:$A$30,0)),"RPE") -> 15 | J35: Your old sheet had decline crunches. Load them — abs are muscle and respond to progressive overload like anything else.
A36: F | B36: 10 min Zone 2 — bike or incline walk | C36: Brisk outdoor walk | D36: 10 min easy row | E36: 10 min | F36: Conversational | G36: — | H36: Aerobic base | I36: — | J36: Same as Day A. Keep it genuinely easy.
A38: DAY D — LOWER, POSTERIOR CHAIN ~80 min Hamstrings · Glutes · Back · Conditioning
A39: # | B39: Exercise (first choice) | C39: Alternative 1 — machine / cable | D39: Alternative 2 — dumbbell / bodyweight | E39: Sets x Reps | F39: Intensity | G39: Rest | H39: Target | I39: Wk1 kg | J39: Coaching note
A40: 1 | B40: Conventional Deadlift | C40: Trap-Bar Deadlift | D40: Heavy Dumbbell RDL | E40: 3 x 4-6 | F40: RPE 8 | G40: 3 min | H40: Full posterior chain | I40: =IFERROR(INDEX(WeightRamp!$C$7:$C$30,MATCH($B40,WeightRamp!$A$7:$A$30,0)),"RPE") -> 47.5 | J40: Your old sheet had 80kg here. Sets of 4-6, never grinding. If form breaks on rep 5, the set ended at rep 4.
A41: 2 | B41: Barbell Hip Thrust | C41: Glute Bridge Machine | D41: Single-Leg Hip Thrust | E41: 3 x 8-12 | F41: RPE 8-9 | G41: 2 min | H41: Glutes | I41: =IFERROR(INDEX(WeightRamp!$C$7:$C$30,MATCH($B41,WeightRamp!$A$7:$A$30,0)),"RPE") -> 42.5 | J41: Weak glutes from sitting all day are the most common cause of a cranky lower back. Chin tucked, ribs down, pause at the top.
A42: 3 | B42: Front Squat | C42: Hack Squat | D42: Goblet Squat | E42: 3 x 8-10 | F42: RPE 8 | G42: 2 min | H42: Quads, upper back | I42: =IFERROR(INDEX(WeightRamp!$C$7:$C$30,MATCH($B42,WeightRamp!$A$7:$A$30,0)),"RPE") -> 25 | J42: Your old sheet listed hack squat with front/goblet as the alternates. Front squat also forces the thoracic spine upright, which is a desk-job bonus.
A43: 4 | B43: Lying Leg Curl | C43: Seated Leg Curl | D43: Slider / Towel Leg Curl | E43: 3 x 10-12 | F43: RPE 9 | G43: 75 sec | H43: Hamstrings | I43: =IFERROR(INDEX(WeightRamp!$C$7:$C$30,MATCH($B43,WeightRamp!$A$7:$A$30,0)),"RPE") -> 27.5 | J43: Different hip angle from Day B's seated version — that's deliberate, it hits the hamstring differently.
A44: 5 | B44: Prisoner Back Extension | C44: 45-degree Back Extension | D44: Bird Dog / Superman | E44: 3 x 12-15 | F44: RPE 8 | G44: 60 sec | H44: Spinal erectors, glutes | I44: =IFERROR(INDEX(WeightRamp!$C$7:$C$30,MATCH($B44,WeightRamp!$A$7:$A$30,0)),"RPE") -> RPE | J44: Straight from your old sheet. Hands behind the head, round up one vertebra at a time. Builds the lower back that sitting slowly dismantles.
A45: 6 | B45: Seated Calf Raise | C45: Standing Calf Raise | D45: Single-Leg Calf Raise | E45: 4 x 12-15 | F45: RPE 9-10 | G45: 60 sec | H45: Soleus | I45: =IFERROR(INDEX(WeightRamp!$C$7:$C$30,MATCH($B45,WeightRamp!$A$7:$A$30,0)),"RPE") -> 25 | J45: Seated hits the soleus, standing hits the gastroc. You want both across the week.
...

Sheet WeightRamp
A1: WEIGHT RAMP — getting back to your college numbers, and past them
A3: Column B is your best from the sheet you sent me, in total kilos including the bar. Columns C to N are what to load each week, rounded to the nearest 2.5kg. Change a number in column B and the whole row recalculates. You said you thought three consistent weeks would get you back to these loads. Three weeks off costs a trained lifter almost nothing — but these numbers are three years old, and you've been running a lighter program since. So the honest answer is week 7-9, not week 3. The ramp below is built to land you there without a shoulder or a lower back giving out in week two. Weeks 10-12 go past your old bests.
A5: Lift | B5: Your old best (kg) | C5: Wk1 | D5: Wk2 | E5: Wk3 | F5: Wk4 | G5: Wk5 | H5: Wk6 | I5: Wk7 | J5: Wk8 | K5: Wk9 | L5: Wk10 | M5: Wk11 | N5: Wk12 | O5: Where this number came from
A6: % of old best | C6: 0.6 | D6: 0.68 | E6: 0.75 | F6: 0.8 | G6: 0.85 | H6: 0.9 | I6: 0.95 | J6: 1 | K6: 0.85 | L6: 1.03 | M6: 1.06 | N6: 1.1 | O6: Wk9 is a deload — planned, not optional. It is how you get weeks 10-12.
A7: Back Squat | B7: 50 | C7: =ROUND($B7*C$6/2.5,0)*2.5 -> 30 | D7: =ROUND($B7*D$6/2.5,0)*2.5 -> 35 | E7: =ROUND($B7*E$6/2.5,0)*2.5 -> 37.5 | F7: =ROUND($B7*F$6/2.5,0)*2.5 -> 40 | G7: =ROUND($B7*G$6/2.5,0)*2.5 -> 42.5 | H7: =ROUND($B7*H$6/2.5,0)*2.5 -> 45 | I7: =ROUND($B7*I$6/2.5,0)*2.5 -> 47.5 | J7: =ROUND($B7*J$6/2.5,0)*2.5 -> 50 | ... N7: =ROUND($B7*N$6/2.5,0)*2.5 -> 55 | O7: Your sheet: 15+15 plates + 20kg bar
A8: Conventional Deadlift | B8: 80 | C8: =ROUND($B8*C$6/2.5,0)*2.5 -> 47.5 | D8: =ROUND($B8*D$6/2.5,0)*2.5 -> 55 | E8: =ROUND($B8*E$6/2.5,0)*2.5 -> 60 | F8: =ROUND($B8*F$6/2.5,0)*2.5 -> 65 | G8: =ROUND($B8*G$6/2.5,0)*2.5 -> 67.5 | H8: =ROUND($B8*H$6/2.5,0)*2.5 -> 72.5 | I8: =ROUND($B8*I$6/2.5,0)*2.5 -> 75 | J8: =ROUND($B8*J$6/2.5,0)*2.5 -> 80 | ... N8: =ROUND($B8*N$6/2.5,0)*2.5 -> 87.5 | O8: Your sheet: 30+30 + 20kg bar
A9: Romanian Deadlift | B9: 70 | C9: =ROUND($B9*C$6/2.5,0)*2.5 -> 42.5 | D9: =ROUND($B9*D$6/2.5,0)*2.5 -> 47.5 | E9: =ROUND($B9*E$6/2.5,0)*2.5 -> 52.5 | F9: =ROUND($B9*F$6/2.5,0)*2.5 -> 55 | G9: =ROUND($B9*G$6/2.5,0)*2.5 -> 60 | H9: =ROUND($B9*H$6/2.5,0)*2.5 -> 62.5 | I9: =ROUND($B9*I$6/2.5,0)*2.5 -> 67.5 | J9: =ROUND($B9*J$6/2.5,0)*2.5 -> 70 | ... N9: =ROUND($B9*N$6/2.5,0)*2.5 -> 77.5 | O9: ESTIMATE — ~85% of your deadlift, standard ratio
A10: Barbell Bench Press | B10: 65 | C10: =ROUND($B10*C$6/2.5,0)*2.5 -> 40 | D10: =ROUND($B10*D$6/2.5,0)*2.5 -> 45 | E10: =ROUND($B10*E$6/2.5,0)*2.5 -> 50 | F10: =ROUND($B10*F$6/2.5,0)*2.5 -> 52.5 | G10: =ROUND($B10*G$6/2.5,0)*2.5 -> 55 | H10: =ROUND($B10*H$6/2.5,0)*2.5 -> 57.5 | I10: =ROUND($B10*I$6/2.5,0)*2.5 -> 62.5 | J10: =ROUND($B10*J$6/2.5,0)*2.5 -> 65 | ... N10: =ROUND($B10*N$6/2.5,0)*2.5 -> 72.5 | O10: Your sheet: 22.5+22.5 + 20kg bar (your progressed set)
A11: Standing Overhead Press | B11: 45 | C11: =ROUND($B11*C$6/2.5,0)*2.5 -> 27.5 | D11: =ROUND($B11*D$6/2.5,0)*2.5 -> 30 | E11: =ROUND($B11*E$6/2.5,0)*2.5 -> 35 | F11: =ROUND($B11*F$6/2.5,0)*2.5 -> 35 | G11: =ROUND($B11*G$6/2.5,0)*2.5 -> 37.5 | H11: =ROUND($B11*H$6/2.5,0)*2.5 -> 40 | I11: =ROUND($B11*I$6/2.5,0)*2.5 -> 42.5 | J11: =ROUND($B11*J$6/2.5,0)*2.5 -> 45 | ... N11: =ROUND($B11*N$6/2.5,0)*2.5 -> 50 | O11: Your sheet: 12.5+12.5 + 20kg bar
A12: Front Squat | B12: 40 | C12: =ROUND($B12*C$6/2.5,0)*2.5 -> 25 | D12: =ROUND($B12*D$6/2.5,0)*2.5 -> 27.5 | E12: =ROUND($B12*E$6/2.5,0)*2.5 -> 30 | F12: =ROUND($B12*F$6/2.5,0)*2.5 -> 32.5 | G12: =ROUND($B12*G$6/2.5,0)*2.5 -> 35 | H12: =ROUND($B12*H$6/2.5,0)*2.5 -> 35 | I12: =ROUND($B12*I$6/2.5,0)*2.5 -> 37.5 | J12: =ROUND($B12*J$6/2.5,0)*2.5 -> 40 | ... N12: =ROUND($B12*N$6/2.5,0)*2.5 -> 45 | O12: ESTIMATE — ~80% of back squat
A13: Barbell Row | B13: 50 | C13: =ROUND($B13*C$6/2.5,0)*2.5 -> 30 | D13: =ROUND($B13*D$6/2.5,0)*2.5 -> 35 | E13: =ROUND($B13*E$6/2.5,0)*2.5 -> 37.5 | F13: =ROUND($B13*F$6/2.5,0)*2.5 -> 40 | G13: =ROUND($B13*G$6/2.5,0)*2.5 -> 42.5 | H13: =ROUND($B13*H$6/2.5,0)*2.5 -> 45 | I13: =ROUND($B13*I$6/2.5,0)*2.5 -> 47.5 | J13: =ROUND($B13*J$6/2.5,0)*2.5 -> 50 | ... N13: =ROUND($B13*N$6/2.5,0)*2.5 -> 55 | O13: ESTIMATE — ~77% of bench, typical for this build
A14: Barbell Hip Thrust | B14: 70 | C14: =ROUND($B14*C$6/2.5,0)*2.5 -> 42.5 | D14: =ROUND($B14*D$6/2.5,0)*2.5 -> 47.5 | E14: =ROUND($B14*E$6/2.5,0)*2.5 -> 52.5 | F14: =ROUND($B14*F$6/2.5,0)*2.5 -> 55 | G14: =ROUND($B14*G$6/2.5,0)*2.5 -> 60 | H14: =ROUND($B14*H$6/2.5,0)*2.5 -> 62.5 | I14: =ROUND($B14*I$6/2.5,0)*2.5 -> 67.5 | J14: =ROUND($B14*J$6/2.5,0)*2.5 -> 70 | ... N14: =ROUND($B14*N$6/2.5,0)*2.5 -> 77.5 | O14: ESTIMATE — ~88% of deadlift for the 8-12 rep range
A15: Pull-Up (weighted when easy) | B15: 0 | C15: BW | D15: BW | E15: BW | F15: BW | G15: BW | H15: BW | I15: BW | J15: BW | K15: BW | L15: BW | M15: BW | N15: BW | O15: Bodyweight. Add load only once 8 clean reps are easy
A16: Lat Pulldown | B16: 45 | C16: =ROUND($B16*C$6/2.5,0)*2.5 -> 27.5 | D16: =ROUND($B16*D$6/2.5,0)*2.5 -> 30 | E16: =ROUND($B16*E$6/2.5,0)*2.5 -> 35 | F16: =ROUND($B16*F$6/2.5,0)*2.5 -> 35 | G16: =ROUND($B16*G$6/2.5,0)*2.5 -> 37.5 | H16: =ROUND($B16*H$6/2.5,0)*2.5 -> 40 | I16: =ROUND($B16*I$6/2.5,0)*2.5 -> 42.5 | J16: =ROUND($B16*J$6/2.5,0)*2.5 -> 45 | ... N16: =ROUND($B16*N$6/2.5,0)*2.5 -> 50 | O16: Your sheet: 45+45+45 across the omni-grip sets
A17: Seated Cable Row | B17: 45 | C17: =ROUND($B17*C$6/2.5,0)*2.5 -> 27.5 | D17: =ROUND($B17*D$6/2.5,0)*2.5 -> 30 | E17: =ROUND($B17*E$6/2.5,0)*2.5 -> 35 | F17: =ROUND($B17*F$6/2.5,0)*2.5 -> 35 | G17: =ROUND($B17*G$6/2.5,0)*2.5 -> 37.5 | H17: =ROUND($B17*H$6/2.5,0)*2.5 -> 40 | I17: =ROUND($B17*I$6/2.5,0)*2.5 -> 42.5 | J17: =ROUND($B17*J$6/2.5,0)*2.5 -> 45 | ... N17: =ROUND($B17*N$6/2.5,0)*2.5 -> 50 | O17: ESTIMATE — matched to your lat pulldown
A18: Rope Face Pull | B18: 50 | C18: =ROUND($B18*C$6/2.5,0)*2.5 -> 30 | D18: =ROUND($B18*D$6/2.5,0)*2.5 -> 35 | E18: =ROUND($B18*E$6/2.5,0)*2.5 -> 37.5 | F18: =ROUND($B18*F$6/2.5,0)*2.5 -> 40 | G18: =ROUND($B18*G$6/2.5,0)*2.5 -> 42.5 | H18: =ROUND($B18*H$6/2.5,0)*2.5 -> 45 | I18: =ROUND($B18*I$6/2.5,0)*2.5 -> 47.5 | J18: =ROUND($B18*J$6/2.5,0)*2.5 -> 50 | ... N18: =ROUND($B18*N$6/2.5,0)*2.5 -> 55 | O18: Your sheet: 43+50
A19: Leg Extension | B19: 45 | C19: =ROUND($B19*C$6/2.5,0)*2.5 -> 27.5 | D19: =ROUND($B19*D$6/2.5,0)*2.5 -> 30 | E19: =ROUND($B19*E$6/2.5,0)*2.5 -> 35 | F19: =ROUND($B19*F$6/2.5,0)*2.5 -> 35 | G19: =ROUND($B19*G$6/2.5,0)*2.5 -> 37.5 | H19: =ROUND($B19*H$6/2.5,0)*2.5 -> 40 | I19: =ROUND($B19*I$6/2.5,0)*2.5 -> 42.5 | J19: =ROUND($B19*J$6/2.5,0)*2.5 -> 45 | ... N19: =ROUND($B19*N$6/2.5,0)*2.5 -> 50 | O19: Your sheet: 45kg
A20: Seated Leg Curl | B20: 45 | C20: =ROUND($B20*C$6/2.5,0)*2.5 -> 27.5 | D20: =ROUND($B20*D$6/2.5,0)*2.5 -> 30 | E20: =ROUND($B20*E$6/2.5,0)*2.5 -> 35 | F20: =ROUND($B20*F$6/2.5,0)*2.5 -> 35 | G20: =ROUND($B20*G$6/2.5,0)*2.5 -> 37.5 | H20: =ROUND($B20*H$6/2.5,0)*2.5 -> 40 | I20: =ROUND($B20*I$6/2.5,0)*2.5 -> 42.5 | J20: =ROUND($B20*J$6/2.5,0)*2.5 -> 45 | ... N20: =ROUND($B20*N$6/2.5,0)*2.5 -> 50 | O20: Your sheet: 45kg
A21: Lying Leg Curl | B21: 45 | C21: =ROUND($B21*C$6/2.5,0)*2.5 -> 27.5 | D21: =ROUND($B21*D$6/2.5,0)*2.5 -> 30 | E21: =ROUND($B21*E$6/2.5,0)*2.5 -> 35 | F21: =ROUND($B21*F$6/2.5,0)*2.5 -> 35 | G21: =ROUND($B21*G$6/2.5,0)*2.5 -> 37.5 | H21: =ROUND($B21*H$6/2.5,0)*2.5 -> 40 | I21: =ROUND($B21*I$6/2.5,0)*2.5 -> 42.5 | J21: =ROUND($B21*J$6/2.5,0)*2.5 -> 45 | ... N21: =ROUND($B21*N$6/2.5,0)*2.5 -> 50 | O21: ESTIMATE — matched to seated leg curl
A22: Standing Calf Raise | B22: 50 | C22: =ROUND($B22*C$6/2.5,0)*2.5 -> 30 | D22: =ROUND($B22*D$6/2.5,0)*2.5 -> 35 | E22: =ROUND($B22*E$6/2.5,0)*2.5 -> 37.5 | F22: =ROUND($B22*F$6/2.5,0)*2.5 -> 40 | G22: =ROUND($B22*G$6/2.5,0)*2.5 -> 42.5 | H22: =ROUND($B22*H$6/2.5,0)*2.5 -> 45 | I22: =ROUND($B22*I$6/2.5,0)*2.5 -> 47.5 | J22: =ROUND($B22*J$6/2.5,0)*2.5 -> 50 | ... N22: =ROUND($B22*N$6/2.5,0)*2.5 -> 55 | O22: Your sheet: 15+15 + 20kg bar
A23: Seated Calf Raise | B23: 40 | C23: =ROUND($B23*C$6/2.5,0)*2.5 -> 25 | D23: =ROUND($B23*D$6/2.5,0)*2.5 -> 27.5 | E23: =ROUND($B23*E$6/2.5,0)*2.5 -> 30 | F23: =ROUND($B23*F$6/2.5,0)*2.5 -> 32.5 | G23: =ROUND($B23*G$6/2.5,0)*2.5 -> 35 | H23: =ROUND($B23*H$6/2.5,0)*2.5 -> 35 | I23: =ROUND($B23*I$6/2.5,0)*2.5 -> 37.5 | J23: =ROUND($B23*J$6/2.5,0)*2.5 -> 40 | ... N23: =ROUND($B23*N$6/2.5,0)*2.5 -> 45 | O23: ESTIMATE — ~80% of standing
A24: Machine Shoulder Press | B24: 43 | C24: =ROUND($B24*C$6/2.5,0)*2.5 -> 25 | D24: =ROUND($B24*D$6/2.5,0)*2.5 -> 30 | E24: =ROUND($B24*E$6/2.5,0)*2.5 -> 32.5 | F24: =ROUND($B24*F$6/2.5,0)*2.5 -> 35 | G24: =ROUND($B24*G$6/2.5,0)*2.5 -> 37.5 | H24: =ROUND($B24*H$6/2.5,0)*2.5 -> 37.5 | I24: =ROUND($B24*I$6/2.5,0)*2.5 -> 40 | J24: =ROUND($B24*J$6/2.5,0)*2.5 -> 42.5 | ... N24: =ROUND($B24*N$6/2.5,0)*2.5 -> 47.5 | O24: Your sheet: 43kg
A25: Incline Dumbbell Press | B25: 22.5 | C25: =ROUND($B25*C$6/2.5,0)*2.5 -> 12.5 | D25: =ROUND($B25*D$6/2.5,0)*2.5 -> 15 | E25: =ROUND($B25*E$6/2.5,0)*2.5 -> 17.5 | F25: =ROUND($B25*F$6/2.5,0)*2.5 -> 17.5 | G25: =ROUND($B25*G$6/2.5,0)*2.5 -> 20 | H25: =ROUND($B25*H$6/2.5,0)*2.5 -> 20 | I25: =ROUND($B25*I$6/2.5,0)*2.5 -> 22.5 | J25: =ROUND($B25*J$6/2.5,0)*2.5 -> 22.5 | ... N25: =ROUND($B25*N$6/2.5,0)*2.5 -> 25 | O25: ESTIMATE, per dumbbell — derived from your 65kg bench
A26: Dumbbell Lateral Raise | B26: 12.5 | C26: =ROUND($B26*C$6/2.5,0)*2.5 -> 7.5 | D26: =ROUND($B26*D$6/2.5,0)*2.5 -> 7.5 | E26: =ROUND($B26*E$6/2.5,0)*2.5 -> 10 | F26: =ROUND($B26*F$6/2.5,0)*2.5 -> 10 | G26: =ROUND($B26*G$6/2.5,0)*2.5 -> 10 | H26: =ROUND($B26*H$6/2.5,0)*2.5 -> 12.5 | I26: =ROUND($B26*I$6/2.5,0)*2.5 -> 12.5 | J26: =ROUND($B26*J$6/2.5,0)*2.5 -> 12.5 | ... N26: =ROUND($B26*N$6/2.5,0)*2.5 -> 15 | O26: Your sheet, per dumbbell: 12.5+12.5
A27: Overhead Cable Tricep Ext. | B27: 31.5 | C27: =ROUND($B27*C$6/2.5,0)*2.5 -> 20 | D27: =ROUND($B27*D$6/2.5,0)*2.5 -> 22.5 | E27: =ROUND($B27*E$6/2.5,0)*2.5 -> 22.5 | F27: =ROUND($B27*F$6/2.5,0)*2.5 -> 25 | G27: =ROUND($B27*G$6/2.5,0)*2.5 -> 27.5 | H27: =ROUND($B27*H$6/2.5,0)*2.5 -> 27.5 | I27: =ROUND($B27*I$6/2.5,0)*2.5 -> 30 | J27: =ROUND($B27*J$6/2.5,0)*2.5 -> 32.5 | ... N27: =ROUND($B27*N$6/2.5,0)*2.5 -> 35 | O27: Your sheet: 31.5kg
... A30: Hammer Curl | B30: 15 | C30: =ROUND($B30*C$6/2.5,0)*2.5 -> 10 | D30: =ROUND($B30*D$6/2.5,0)*2.5 -> 10 | E30: =ROUND($B30*E$6/2.5,0)*2.5 -> 12.5 | F30: =ROUND($B30*F$6/2.5,0)*2.5 -> 12.5 | G30: =ROUND($B30*G$6/2.5,0)*2.5 -> 12.5 | H30: =ROUND($B30*H$6/2.5,0)*2.5 -> 12.5 | I30: =ROUND($B30*I$6/2.5,0)*2.5 -> 15 | J30: =ROUND($B30*J$6/2.5,0)*2.5 -> 15 | ... N30: =ROUND($B30*N$6/2.5,0)*2.5 -> 17.5 | O30: ESTIMATE, per dumbbell — from your 25kg shrug
A32: HOW TO PROGRESS ONCE THE RAMP RUNS OUT
A33: Double progression | B33: Hit the top of the rep range on every set, then add 2.5kg (upper body) or 5kg (lower body) and drop back to the bottom of the range. Repeat. That's the whole method.
A34: Leave reps in reserve | B34: RPE 8 means two clean reps left in the tank. Training to failure on every set in a calorie deficit buys you fatigue, not muscle. Save failure for the isolation work — laterals, curls, leg extensions.
A35: Deload when the sheet says so | B35: Week 9 drops to 85%. Do not skip it because you feel fine — you feel fine because the fatigue hasn't surfaced yet. Weeks 10-12 are the payoff for taking it.
A36: If a week goes badly | B36: Two bad sessions in a row on the same lift means you repeat the week rather than pushing. In a deficit, on 6 hours of sleep, under work stress, the ramp will occasionally need to wait. That's the system working, not failing.
A38: Rows marked ESTIMATE in the last column were not in the sheet you sent me — they're derived from your other lifts using standard strength ratios. Treat them as a starting point: if week 1 feels far too easy or far too hard, correct the yellow cell in column B and the whole row re-paces itself.

Sheet Nutrition
A1: NUTRITION — every number below is a formula off your bodyweight
A3: YOUR INPUTS — edit the yellow cells only, everything else recalculates
A4: Height (cm) | B4: 175 | D4: 5'9" as you gave it
A5: Current weight (kg) | B5: 79 | D5: Update this every Sunday — the whole sheet re-paces off it
A6: Age (years) | B6: 28 | D6: ESTIMATE — change it, it shifts your BMR by ~5 kcal per year
A7: Target weight (kg) | B7: 76 | D7: Your stated target. At 175cm that's a BMI of 24.8
A8: Activity multiplier | B8: 1.5 | D8: Desk job + 4-5 gym sessions. Drop to 1.4 in a light week, 1.55 if you also hit 12k steps
A9: Daily calorie deficit | B9: 450 | D9: ~0.5% of bodyweight lost per week — the rate the research links to the best muscle retention
A10: Protein (g per kg) | B10: 2 | D10: Deficit-adjusted. Meta-analyses land on 1.6-2.2 g/kg; ~1.9-2.0 is the sweet spot when dieting
A11: Fat (g per kg) | B11: 0.8 | D11: Floor for hormone function. Going lower buys carbs you don't need badly enough
A12: Mon-Fri calorie target | B12: 2000 | D12: Deliberately under your daily target — this is what funds the weekend
A14: YOUR DAILY TARGETS
A15: BMR (Mifflin-St Jeor) | B15: =10*B5+6.25*B4-5*B6+5 -> 1748.75 | C15: kcal | D15: What you'd burn lying in bed all day
A16: TDEE — maintenance | B16: =B15*B8 -> 2623.125 | C16: kcal | D16: What you burn on a normal training day. Eat this and weight holds
A17: DAILY CALORIE TARGET | B17: =B16-B9 -> 2173.125 | C17: kcal | D17: Your average across the week. Not a hard daily cap — see the weekend section below
A18: Protein | B18: =B5*B10 -> 158 | C18: g | D18: The single most important number on this sheet. Hit it before you worry about anything else
A19: Fat | B19: =B5*B11 -> 63.2 | C19: g | D19: Prioritise olive oil, nuts, eggs, oily fish. Not fried food
A20: Carbohydrate | B20: =(B17-B18*4-B19*9)/4 -> 243.08125 | C20: g | D20: Fuel. Most of it around training — this is what lets you keep the weight on the bar while cutting
A21: Fibre | B21: =B17/1000*14 -> 30.42375 | C21: g | D21: 14g per 1000 kcal, the standard recommendation. Fibre is also the cheapest way to feel full on fewer calories
A22: Water | B22: =ROUND(B5*0.035,1) -> 2.8 | C22: L | D22: More on training days. Add 500ml per gym session
A24: MACRO SPLIT — sanity check
A25: Protein — % of calories | B25: =B18*4/B17 -> 0.29082542 | D25: Sits high because you're cutting. That's intentional
A26: Fat — % of calories | B26: =B19*9/B17 -> 0.26174288 | D26: Low-normal. Fine, and easy to hit
A27: Carbs — % of calories | B27: =B20*4/B17 -> 0.44743169 | D27: The flexible one. Shift carbs to fat if you prefer, keeping calories equal
A29: THE WEEKEND BANK — how the junk and sweets fit in without breaking anything
A30: You said you can't cut junk and sweets completely, and that it happens at the weekend. Good — so don't try. Fat loss responds to the weekly calorie total, not the daily one. Eat at the Mon-Fri number in cell B12 and the shortfall banks up. By Saturday there's a real allowance sitting there. Not 'a small square of dark chocolate'. An actual dessert, or a takeaway, eaten without any of the guilt spiral that makes the next week worse.
A32: Weekly calorie budget | B32: =B17*7 -> 15211.875 | C32: kcal | D32: Your daily target x 7. This is the number that actually matters
A33: Mon-Fri intake (5 days) | B33: =B12*5 -> 10000 | C33: kcal | D33: At the weekday target in B12
A34: Left for Sat + Sun | B34: =B32-B33 -> 5211.875 | C34: kcal | D34: Banked, and yours to spend
A35: Per weekend day | B35: =B34/2 -> 2605.9375 | C35: kcal | D35: Split evenly, or blow it all on one day — the week doesn't care
A36: Spare vs an average day | B36: =B35-B17 -> 432.8125 | C36: kcal | D36: This is your junk-food budget. Real food still needs to cover the protein target
A38: Two rules that keep this honest. First: protein does not get a day off. Hit cell B18 on Saturday and Sunday too — that is what stops the weekend costing you muscle rather than just calories. Second: if the weekend regularly overshoots the number in B36, don't punish Monday with a crash day. Lower B12 by 100 and let the bank grow bigger instead.
A40: TIMELINE — 79kg to 76kg
A41: Weekly fat loss rate | B41: =B9*7/7700 -> 0.40909091 | C41: kg/wk | D41: 7,700 kcal per kg of fat. Inside the 0.5-1% of bodyweight per week that preserves muscle best
A42: Kilos to lose | B42: =B5-B7 -> 3 | C42: kg
A43: Weeks at perfect adherence | B43: =B42/B41 -> 7.3333333 | C43: weeks | D43: Theoretical. Nobody is perfect
A44: Weeks at 80% adherence | B44: =B43/0.8 -> 9.1666667 | C44: weeks | D44: REALISTIC. Plan around this number, not the one above
A46: One thing worth flagging: 76kg is a scale number, and the scale is a poor judge of what you're actually asking for. You want a flatter stomach, visible abs and no extra bulk. If you drop 3kg of fat while holding your muscle, you'll be leaner at 76kg than you'd guess. But if training goes well and you regain a kilo of the muscle you had in college, the scale might read 77 while your waist is 4cm smaller and the abs are more visible. That would be a better outcome, and the scale would call it a failure. Track the waist measurement in the Tracker sheet alongside the weight — where those two disagree, the waist is telling the truth.
A48: A DAY THAT HITS THE NUMBERS — example, not a prescription
A49: Meal | B49: kcal | C49: Protein | D49: What it looks like | E49: Why it's there
...

Sheet Nutrients
A1: MICRONUTRIENTS — the things a calorie tracker won't tell you you're missing
A3: Calories and macros decide your body composition. These decide whether you feel good doing it — energy, sleep, mood, recovery, joint health. On a desk job in a calorie deficit under work stress, the ones below are the ones that realistically go short.
A5: PRIORITY NUTRIENTS
A6: Nutrient | B6: Daily target | C6: Best food sources | D6: Why it matters for you specifically
A7: Omega-3 (EPA + DHA) | B7: 1,000-2,000 mg | C7: Salmon (~2,000mg per 100g), mackerel, sardines, shrimp (~300mg per 100g, plus astaxanthin and 20g protein at 100 kcal). Two oily-fish meals a week does it. | D7: The one you flagged, and rightly. Anti-inflammatory, supports recovery between sessions, and there's reasonable evidence for mood and cognition — relevant if stress and overthinking are part of the picture. Most guidelines set a floor of 250-500mg; 1-2g is the range used in the training and inflammation literature.
A8: Omega-3 (ALA, plant) | B8: 1,600 mg | C8: Chia seeds (~5,000mg per 30g), flaxseed, walnuts. 30g of chia in yoghurt or oats covers it several times over. | D8: Conversion of ALA to EPA/DHA in humans is poor — under 10%. So chia is genuinely worth eating for its fibre and minerals, but it does not replace the fish. Eat both.
A9: Fibre | B9: =TEXT(Nutrition!B21,"0")&" g" -> 30 g | C9: Oats, beans, lentils, chia (10g per 30g), berries, broccoli, whole fruit rather than juice. | D9: Underrated for exactly your situation. Fibre slows gastric emptying, which flattens the blood-sugar swings that drive stress snacking. It's also the cheapest satiety you can buy in a deficit.
A10: Vitamin D3 | B10: 1,000-2,000 IU | C10: Sunlight, oily fish, egg yolks, fortified milk. Realistically a supplement if you're indoors 9-to-5. | D10: Deficiency is close to universal in desk workers. Affects bone density, immune function, muscle function and mood. Worth a blood test rather than guessing — it's the one nutrient here where a lab result genuinely changes the dose.
A11: Magnesium | B11: 400-420 mg | C11: Pumpkin seeds, almonds, spinach, dark chocolate (a legitimate reason to keep some in the house), black beans. | D11: Involved in muscle contraction and sleep quality. Training hard and sleeping badly both drain it, and you've described a stress load that tends to come with poor sleep. Glycinate form if you supplement — better absorbed, and easier on the gut.
A12: Creatine monohydrate | B12: 3-5 g | C12: Red meat and fish contain small amounts. Practically, this is one you supplement. | D12: The most studied and most reliably effective legal supplement there is. Helps you hold strength while cutting, which is exactly the fight you're in. No loading phase needed, monohydrate only, timing is irrelevant. Ignore anything sold as a fancier version.
A13: Zinc | B13: 11 mg | C13: Oysters, beef, pumpkin seeds, chickpeas, cashews. | D13: Immune function and testosterone production. Depletes through sweat, so training frequency matters here.
A14: Iron | B14: 8 mg | C14: Red meat, lentils, spinach, fortified cereal. Pair plant sources with vitamin C to absorb them. | D14: Oxygen transport — directly tied to the stamina goal. Low iron shows up as fatigue and breathlessness on the intervals long before any blood test flags it.
A15: Potassium | B15: 3,400 mg | C15: Bananas, potatoes, spinach, beans, yoghurt. | D15: Balances sodium and regulates blood pressure. Most people eat far too little relative to salt.
A16: Calcium | B16: 1,000 mg | C16: Dairy, fortified plant milk, sardines with bones, leafy greens. | D16: Bone density, and it's actively protective when you're lifting heavy twice a week on lower body.
A17: Vitamin B12 | B17: 2.4 mcg | C17: Meat, fish, eggs, dairy. Fortified foods if you eat little animal protein. | D17: Red blood cell formation and nerve function. Easy to hit on your diet — flagged mainly so you notice if you cut meat.
A18: Sodium | B18: under 2,300 mg | C18: Not something to add. The issue is packaged food, restaurant meals and the weekend takeaway. | D18: The one to keep down rather than up. High sodium also causes water retention that makes the scale jump 1-2kg after a weekend — which is water, not fat, and gone by Wednesday.
A20: HIGH-PROTEIN FOODS RANKED BY WHAT THEY COST YOU IN CALORIES
A21: Food (100g cooked) | B21: Protein (g) | C21: Calories | D21: Notes
A22: Shrimp / prawns | B22: 24 | C22: 99 | D22: Best protein-to-calorie ratio on this list, plus omega-3, selenium and B12. You mentioned it — it earns the spot.
A23: White fish (cod, tilapia) | B23: 23 | C23: 105 | D23: Almost pure protein. Bland on its own, which is what spice is for.
A24: Chicken breast | B24: 31 | C24: 165 | D24: The default. Gets boring fast — rotate it or you'll stop eating it.
A25: Egg whites | B25: 11 | C25: 52 | D25: Cheap volume protein. Keep some yolks though, that's where the nutrients live.
A26: Greek yoghurt (0%) | B26: 10 | C26: 59 | D26: Excellent evening food. Casein digests slowly, so it holds through the night.
A27: Cottage cheese | B27: 11 | C27: 98 | D27: Same logic. Better savoury than most people expect.
A28: Tuna (in water) | B28: 25 | C28: 116 | D28: Convenient. Cap it at 3-4 tins a week for mercury.
A29: Salmon | B29: 25 | C29: 208 | D29: Higher calorie, and worth every one of them for the EPA and DHA.
A30: Lean beef (sirloin) | B30: 27 | C30: 206 | D30: Iron, zinc, creatine. Once or twice a week.
A31: Whey protein (1 scoop) | B31: 24 | C31: 120 | D31: Not magic, just convenient. Useful for closing a 30g gap at 9pm.
A32: Lentils | B32: 9 | C32: 116 | D32: Protein plus 8g of fibre. Doing two jobs at once.
A33: Tofu (firm) | B33: 17 | C33: 144 | D33: Complete protein, and a genuine break from meat.
... A35: Chia seeds (30g) | B35: 5 | C35: 138 | D35: Not really a protein food. Here for 10g fibre and 5g ALA omega-3.
A37: Supplements worth the money, in order: creatine monohydrate, vitamin D3, omega-3, magnesium glycinate. Whey if it makes the protein target easier to hit. That is the whole list. Fat burners, testosterone boosters, BCAAs and detox anything do nothing that a decent diet doesn't already do. Check with a doctor before starting supplements if you take any medication — omega-3 at higher doses interacts with blood thinners in particular.

Sheet Tracker
A1: WEEKLY TRACKER — log eight numbers on Sunday, get told what to fix
A3: Fill the yellow columns once a week, same time, same conditions — Sunday morning, after the toilet, before eating. Weigh daily if you like but only log the 7-day average; daily weight swings 1-2kg on water and means nothing. Measure the waist at the navel, relaxed, not sucked in. Columns K to N calculate themselves.
A5: Wk | B5: Week start | C5: Weight (kg) | D5: Waist (cm) | E5: Gym days | F5: Cardio / sport | G5: Avg kcal | H5: Avg protein (g) | I5: Avg steps | J5: Sleep (hrs) | K5: Target wt | L5: Variance | M5: Status | N5: What to do about it
A6: 1 | K6: =Nutrition!$B$5-(1*Nutrition!$B$41) -> 78.590909 | L6: =IF(C6="","",C6-K6) | M6: =IF(C6="","—",IF(L6<=0.3,"On track",IF(L6<=0.8,"Slightly behind","Behind"))) -> — | N6: =IF(C6="","Log this week to get feedback",IF(H6<Nutrition!$B$18*0.85,"PROTEIN SHORT. Below 85% of target. In a deficit this is the fastest way to lose muscle instead of fat — you get smaller, not leaner, and the abs never show. Fix this before anything else.",IF(E6<4,"SESSIONS SHORT. Under 4 lifting days means a muscle dropped to once-a-week frequency. Strength regain stalls and the deficit starts eating muscle. One missed week is fine; two in a row is a pattern.",IF(G6>Nutrition!$B$17*1.12,"CALORIES OVER by more than 12%. Fat loss stops here regardless of how hard you train. Check the weekend — that is almost always where it goes.",IF(J6<6.5,"SLEEP SHORT. Under 6.5 hours raises cortisol, blunts recovery, and measurably increases appetite the next day. This is upstream of the stress eating, not separate from it.",IF(I6<7000,"STEPS LOW. Under 7,000 a day means the desk job is winning. Non-exercise movement burns more than your gym sessions do — a 20 minute walk at lunch closes most of this gap.",IF(L6>0.8,"BEHIND PACE. Everything logged looks fine, so the likely culprit is untracked calories — cooking oil, drinks, weekend portions. Weigh your food for one honest week before changing anything else.",IF(AND(D6<>"",D6>=D5,1>2),"WAIST NOT MOVING even though weight is. Usually water retention from a salty weekend. Give it another week before touching anything.","On track. Nothing to fix — keep doing exactly this.")))))))) -> Log this week to get feedback
A7: 2 | K7: =Nutrition!$B$5-(2*Nutrition!$B$41) -> 78.181818 | L7: =IF(C7="","",C7-K7) | M7: =IF(C7="","—",IF(L7<=0.3,"On track",IF(L7<=0.8,"Slightly behind","Behind"))) -> — | N7: =IF(C7="","Log this week to get feedback",IF(H7<Nutrition!$B$18*0.85,"PROTEIN SHORT. Below 85% of target. In a deficit this is the fastest way to lose muscle instead of fat — you get smaller, not leaner, and the abs never show. Fix this before anything else.",IF(E7<4,"SESSIONS SHORT. Under 4 lifting days means a muscle dropped to once-a-week frequency. Strength regain stalls and the deficit starts eating muscle. One missed week is fine; two in a row is a pattern.",IF(G7>Nutrition!$B$17*1.12,"CALORIES OVER by more than 12%. Fat loss stops here regardless of how hard you train. Check the weekend — that is almost always where it goes.",IF(J7<6.5,"SLEEP SHORT. Under 6.5 hours raises cortisol, blunts recovery, and measurably increases appetite the next day. This is upstream of the stress eating, not separate from it.",IF(I7<7000,"STEPS LOW. Under 7,000 a day means the desk job is winning. Non-exercise movement burns more than your gym sessions do — a 20 minute walk at lunch closes most of this gap.",IF(L7>0.8,"BEHIND PACE. Everything logged looks fine, so the likely culprit is untracked calories — cooking oil, drinks, weekend portions. Weigh your food for one honest week before changing anything else.",IF(AND(D7<>"",D7>=D6,2>2),"WAIST NOT MOVING even though weight is. Usually water retention from a salty weekend. Give it another week before touching anything.","On track. Nothing to fix — keep doing exactly this.")))))))) -> Log this week to get feedback
A8: 3 | K8: =Nutrition!$B$5-(3*Nutrition!$B$41) -> 77.772727 | L8: =IF(C8="","",C8-K8) | M8: =IF(C8="","—",IF(L8<=0.3,"On track",IF(L8<=0.8,"Slightly behind","Behind"))) -> — | N8: =IF(C8="","Log this week to get feedback",IF(H8<Nutrition!$B$18*0.85,"PROTEIN SHORT. Below 85% of target. In a deficit this is the fastest way to lose muscle instead of fat — you get smaller, not leaner, and the abs never show. Fix this before anything else.",IF(E8<4,"SESSIONS SHORT. Under 4 lifting days means a muscle dropped to once-a-week frequency. Strength regain stalls and the deficit starts eating muscle. One missed week is fine; two in a row is a pattern.",IF(G8>Nutrition!$B$17*1.12,"CALORIES OVER by more than 12%. Fat loss stops here regardless of how hard you train. Check the weekend — that is almost always where it goes.",IF(J8<6.5,"SLEEP SHORT. Under 6.5 hours raises cortisol, blunts recovery, and measurably increases appetite the next day. This is upstream of the stress eating, not separate from it.",IF(I8<7000,"STEPS LOW. Under 7,000 a day means the desk job is winning. Non-exercise movement burns more than your gym sessions do — a 20 minute walk at lunch closes most of this gap.",IF(L8>0.8,"BEHIND PACE. Everything logged looks fine, so the likely culprit is untracked calories — cooking oil, drinks, weekend portions. Weigh your food for one honest week before changing anything else.",IF(AND(D8<>"",D8>=D7,3>2),"WAIST NOT MOVING even though weight is. Usually water retention from a salty weekend. Give it another week before touching anything.","On track. Nothing to fix — keep doing exactly this.")))))))) -> Log this week to get feedback
A9: 4 | K9: =Nutrition!$B$5-(4*Nutrition!$B$41) -> 77.363636 | L9: =IF(C9="","",C9-K9) | M9: =IF(C9="","—",IF(L9<=0.3,"On track",IF(L9<=0.8,"Slightly behind","Behind"))) -> — | N9: =IF(C9="","Log this week to get feedback",IF(H9<Nutrition!$B$18*0.85,"PROTEIN SHORT. Below 85% of target. In a deficit this is the fastest way to lose muscle instead of fat — you get smaller, not leaner, and the abs never show. Fix this before anything else.",IF(E9<4,"SESSIONS SHORT. Under 4 lifting days means a muscle dropped to once-a-week frequency. Strength regain stalls and the deficit starts eating muscle. One missed week is fine; two in a row is a pattern.",IF(G9>Nutrition!$B$17*1.12,"CALORIES OVER by more than 12%. Fat loss stops here regardless of how hard you train. Check the weekend — that is almost always where it goes.",IF(J9<6.5,"SLEEP SHORT. Under 6.5 hours raises cortisol, blunts recovery, and measurably increases appetite the next day. This is upstream of the stress eating, not separate from it.",IF(I9<7000,"STEPS LOW. Under 7,000 a day means the desk job is winning. Non-exercise movement burns more than your gym sessions do — a 20 minute walk at lunch closes most of this gap.",IF(L9>0.8,"BEHIND PACE. Everything logged looks fine, so the likely culprit is untracked calories — cooking oil, drinks, weekend portions. Weigh your food for one honest week before changing anything else.",IF(AND(D9<>"",D9>=D8,4>2),"WAIST NOT MOVING even though weight is. Usually water retention from a salty weekend. Give it another week before touching anything.","On track. Nothing to fix — keep doing exactly this.")))))))) -> Log this week to get feedback
A10: 5 | K10: =Nutrition!$B$5-(5*Nutrition!$B$41) -> 76.954545 | L10: =IF(C10="","",C10-K10) | M10: =IF(C10="","—",IF(L10<=0.3,"On track",IF(L10<=0.8,"Slightly behind","Behind"))) -> — | N10: =IF(C10="","Log this week to get feedback",IF(H10<Nutrition!$B$18*0.85,"PROTEIN SHORT. Below 85% of target. In a deficit this is the fastest way to lose muscle instead of fat — you get smaller, not leaner, and the abs never show. Fix this before anything else.",IF(E10<4,"SESSIONS SHORT. Under 4 lifting days means a muscle dropped to once-a-week frequency. Strength regain stalls and the deficit starts eating muscle. One missed week is fine; two in a row is a pattern.",IF(G10>Nutrition!$B$17*1.12,"CALORIES OVER by more than 12%. Fat loss stops here regardless of how hard you train. Check the weekend — that is almost always where it goes.",IF(J10<6.5,"SLEEP SHORT. Under 6.5 hours raises cortisol, blunts recovery, and measurably increases appetite the next day. This is upstream of the stress eating, not separate from it.",IF(I10<7000,"STEPS LOW. Under 7,000 a day means the desk job is winning. Non-exercise movement burns more than your gym sessions do — a 20 minute walk at lunch closes most of this gap.",IF(L10>0.8,"BEHIND PACE. Everything logged looks fine, so the likely culprit is untracked calories — cooking oil, drinks, weekend portions. Weigh your food for one honest week before changing anything else.",IF(AND(D10<>"",D10>=D9,5>2),"WAIST NOT MOVING even though weight is. Usually water retention from a salty weekend. Give it another week before touching anything.","On track. Nothing to fix — keep doing exactly this.")))))))) -> Log this week to get feedback
A11: 6 | K11: =Nutrition!$B$5-(6*Nutrition!$B$41) -> 76.545455 | L11: =IF(C11="","",C11-K11) | M11: =IF(C11="","—",IF(L11<=0.3,"On track",IF(L11<=0.8,"Slightly behind","Behind"))) -> — | N11: =IF(C11="","Log this week to get feedback",IF(H11<Nutrition!$B$18*0.85,"PROTEIN SHORT. Below 85% of target. In a deficit this is the fastest way to lose muscle instead of fat — you get smaller, not leaner, and the abs never show. Fix this before anything else.",IF(E11<4,"SESSIONS SHORT. Under 4 lifting days means a muscle dropped to once-a-week frequency. Strength regain stalls and the deficit starts eating muscle. One missed week is fine; two in a row is a pattern.",IF(G11>Nutrition!$B$17*1.12,"CALORIES OVER by more than 12%. Fat loss stops here regardless of how hard you train. Check the weekend — that is almost always where it goes.",IF(J11<6.5,"SLEEP SHORT. Under 6.5 hours raises cortisol, blunts recovery, and measurably increases appetite the next day. This is upstream of the stress eating, not separate from it.",IF(I11<7000,"STEPS LOW. Under 7,000 a day means the desk job is winning. Non-exercise movement burns more than your gym sessions do — a 20 minute walk at lunch closes most of this gap.",IF(L11>0.8,"BEHIND PACE. Everything logged looks fine, so the likely culprit is untracked calories — cooking oil, drinks, weekend portions. Weigh your food for one honest week before changing anything else.",IF(AND(D11<>"",D11>=D10,6>2),"WAIST NOT MOVING even though weight is. Usually water retention from a salty weekend. Give it another week before touching anything.","On track. Nothing to fix — keep doing exactly this.")))))))) -> Log this week to get feedback
A12: 7 | K12: =Nutrition!$B$5-(7*Nutrition!$B$41) -> 76.136364 | L12: =IF(C12="","",C12-K12) | M12: =IF(C12="","—",IF(L12<=0.3,"On track",IF(L12<=0.8,"Slightly behind","Behind"))) -> — | N12: =IF(C12="","Log this week to get feedback",IF(H12<Nutrition!$B$18*0.85,"PROTEIN SHORT. Below 85% of target. In a deficit this is the fastest way to lose muscle instead of fat — you get smaller, not leaner, and the abs never show. Fix this before anything else.",IF(E12<4,"SESSIONS SHORT. Under 4 lifting days means a muscle dropped to once-a-week frequency. Strength regain stalls and the deficit starts eating muscle. One missed week is fine; two in a row is a pattern.",IF(G12>Nutrition!$B$17*1.12,"CALORIES OVER by more than 12%. Fat loss stops here regardless of how hard you train. Check the weekend — that is almost always where it goes.",IF(J12<6.5,"SLEEP SHORT. Under 6.5 hours raises cortisol, blunts recovery, and measurably increases appetite the next day. This is upstream of the stress eating, not separate from it.",IF(I12<7000,"STEPS LOW. Under 7,000 a day means the desk job is winning. Non-exercise movement burns more than your gym sessions do — a 20 minute walk at lunch closes most of this gap.",IF(L12>0.8,"BEHIND PACE. Everything logged looks fine, so the likely culprit is untracked calories — cooking oil, drinks, weekend portions. Weigh your food for one honest week before changing anything else.",IF(AND(D12<>"",D12>=D11,7>2),"WAIST NOT MOVING even though weight is. Usually water retention from a salty weekend. Give it another week before touching anything.","On track. Nothing to fix — keep doing exactly this.")))))))) -> Log this week to get feedback
A13: 8 | K13: =Nutrition!$B$5-(8*Nutrition!$B$41) -> 75.727273 | L13: =IF(C13="","",C13-K13) | M13: =IF(C13="","—",IF(L13<=0.3,"On track",IF(L13<=0.8,"Slightly behind","Behind"))) -> — | N13: =IF(C13="","Log this week to get feedback",IF(H13<Nutrition!$B$18*0.85,"PROTEIN SHORT. Below 85% of target. In a deficit this is the fastest way to lose muscle instead of fat — you get smaller, not leaner, and the abs never show. Fix this before anything else.",IF(E13<4,"SESSIONS SHORT. Under 4 lifting days means a muscle dropped to once-a-week frequency. Strength regain stalls and the deficit starts eating muscle. One missed week is fine; two in a row is a pattern.",IF(G13>Nutrition!$B$17*1.12,"CALORIES OVER by more than 12%. Fat loss stops here regardless of how hard you train. Check the weekend — that is almost always where it goes.",IF(J13<6.5,"SLEEP SHORT. Under 6.5 hours raises cortisol, blunts recovery, and measurably increases appetite the next day. This is upstream of the stress eating, not separate from it.",IF(I13<7000,"STEPS LOW. Under 7,000 a day means the desk job is winning. Non-exercise movement burns more than your gym sessions do — a 20 minute walk at lunch closes most of this gap.",IF(L13>0.8,"BEHIND PACE. Everything logged looks fine, so the likely culprit is untracked calories — cooking oil, drinks, weekend portions. Weigh your food for one honest week before changing anything else.",IF(AND(D13<>"",D13>=D12,8>2),"WAIST NOT MOVING even though weight is. Usually water retention from a salty weekend. Give it another week before touching anything.","On track. Nothing to fix — keep doing exactly this.")))))))) -> Log this week to get feedback
